Workbook

Sheet 세부채점표
A1: 문제 | B1: 항목 | C1: 세부항목 | E1: 배점 | F1: 1 | G1: 2 | H1: 3 | I1: 4 | J1: 5 | K1: 6 | L1: 7 | M1: 8 | N1: 9 | O1: 10
B2: 공통사항 | C2: 1 | D2: 로고 메인 이동 (폼 10개) | E2: 1
C3: 2 | D3: 경고 메시지/정보 메시지 | E3: 0.2
C4: 3 | D4: 상품이미지, 회원이미지 blbo | E4: 1
A5: 소계 | E5: =SUM(E2:E4) -> 2.2 | F5: =SUM(F2:F4) -> 0 | G5: =SUM(G2:G4) -> 0 | H5: =SUM(H2:H4) -> 0 | I5: =SUM(I2:I4) -> 0 | J5: =SUM(J2:J4) -> 0 | K5: =SUM(K2:K4) -> 0 | L5: =SUM(L2:L4) -> 0 | ... O5: =SUM(O2:O4) -> 0
A6: 문제 1-1 | B6: 메인 폼 | C6: 1 | D6: 디자인 및 상품 업로드 | E6: 1
C7: 2 | D7: 상품 글자 15자이상 … | E7: 0.2
C8: 3 | D8: 할인율 계산 | E8: 0.5
C9: 4 | D9: 상품 클릭 제어 (로그인전 / 로그인후 이동) | E9: 0.2
C10: 5 | D10: 가격순(↓), 가격순(↑), 별점순(↓) 버튼 제어 | E10: 1.5
C11: 6 | D11: 유저 이미지 클릭 관리폼 이동 | E11: 0.1
C12: 7 | D12: 검색 빈칸 - 전체 | E12: 0.2
C13: 8 | D13: 검색시 1개 카테고리 트리 제어 | E13: 0.5
C14: 9 | D14: 검색시 2개이상 카테고리시 전체 제어 | E14: 0.5
C15: 10 | D15: 로그인시 처리 | E15: 0.4
C16: 11 | D16: 전체클릭시 전체 제어 | E16: 0.2
C17: 12 | D17: 카테고리 클릭시 검색 | E17: 0.2
A18: 소계 | E18: =SUM(E6:E17) -> 5.5 | F18: =SUM(F6:F17) -> 0 | G18: =SUM(G6:G17) -> 0 | H18: =SUM(H6:H17) -> 0 | I18: =SUM(I6:I17) -> 0 | J18: =SUM(J6:J17) -> 0 | K18: =SUM(K6:K17) -> 0 | L18: =SUM(L6:L17) -> 0 | ... O18: =SUM(O6:O17) -> 0
A19: 문제 1-2 | B19: 로그인 | C19: 1 | D19: 폼 디자인 | E19: 0.2
C20: 2 | D20: 빈칸제어 | E20: 0.1
C21: 3 | D21: 미 일치 제어 | E21: 0.3
C22: 4 | D22: 일치 제어 | E22: 0.3
C23: 4 | D23: 폼이동 | E23: 0.1
A24: 소계 | E24: =SUM(E19:E23) -> 1 | F24: =SUM(F19:F23) -> 0 | G24: =SUM(G19:G23) -> 0 | H24: =SUM(H19:H23) -> 0 | I24: =SUM(I19:I23) -> 0 | J24: =SUM(J19:J23) -> 0 | K24: =SUM(K19:K23) -> 0 | L24: =SUM(L19:L23) -> 0 | ... O24: =SUM(O19:O23) -> 0
A25: 문제 1-3 | B25: 상품 | C25: 1 | D25: 폼디자인 및 정보업로드 | E25: 1
C26: 2 | D26: 사이즈 제어 | E26: 0.4
C27: 3 | D27: 서브카테고리 클릭 | E27: 0.4
C28: 4 | D28: 서브 클릭시 초기와 | E28: 0.2
C29: 5 | D29: 할은금액 계산 | E29: 0.5
C30: 6 | D30: 구매버튼 제어 | E30: 0.2
C31: 7 | D31: 장바구니 제어 | E31: 0.2
C32: 8 | D32: 20글자 이상... | E32: 0.2
C33: 9 | D33: 별점 | E33: 0.5
A34: 소계 | E34: =SUM(E25:E33) -> 3.6 | F34: =SUM(F25:F33) -> 0 | G34: =SUM(G25:G33) -> 0 | H34: =SUM(H25:H33) -> 0 | I34: =SUM(I25:I33) -> 0 | J34: =SUM(J25:J33) -> 0 | K34: =SUM(K25:K33) -> 0 | L34: =SUM(L25:L33) -> 0 | ... O34: =SUM(O25:O33) -> 0
A35: 문제 1-4 | B35: 마이페이지 | C35: 1 | D35: 정보수정 디자인 | E35: 0.5
C36: 2 | D36: 로그인 회원 정보 | E36: 0.5
C37: 3 | D37: 충전하기 이동 | E37: 0.1
C38: 4 | D38: 이미지 저장 | E38: 0.5
C39: 5 | D39: 미수정 제어 | E39: 0.2
C40: 6 | D40: 생년월일 제어 | E40: 0.2
...

Sheet 전산용
A1: 문제 | B1: 항목 | C1: 세부항목 | E1: 배점 | F1: 1 | G1: 2 | H1: 3 | I1: 4 | J1: 5 | K1: 6 | L1: 7 | M1: 8 | N1: 9 | O1: 10
B2: 공통사항 | C2: 1 | D2: 로고 메인 이동 (폼 9개) | E2: =세부채점표!E2 -> 1
C3: 2 | D3: 경고 메시지/정보 메시지 | E3: =세부채점표!E3 -> 0.2
C4: 3 | D4: 상품, 회원이미지 blob | E4: =세부채점표!E4 -> 1
A5: 소계 | E5: =SUM(E2:E4) -> 2.2 | F5: =SUM(F2:F4) -> 0 | G5: =SUM(G2:G4) -> 0 | H5: =SUM(H2:H4) -> 0 | I5: =SUM(I2:I4) -> 0 | J5: =SUM(J2:J4) -> 0 | K5: =SUM(K2:K4) -> 0 | L5: =SUM(L2:L4) -> 0 | ... O5: =SUM(O2:O4) -> 0
A6: 문제 1-1 | B6: 메인 폼 | C6: 1 | D6: 디자인 | E6: =세부채점표!E6 -> 1
C7: 2 | D7: 상품 글자 15자이상 … | E7: =세부채점표!E7 -> 0.2
C8: 3 | D8: 할인율 계산 | E8: =세부채점표!E8 -> 0.5
C9: 4 | D9: 상품 클릭 제어 (로그인전 / 로그인후 이동) | E9: =세부채점표!E9 -> 0.2
C10: 5 | D10: 가격순(↓), 가격순(↑), 별점순(↓) 버튼 제어 | E10: =세부채점표!E10 -> 1.5
C11: 6 | D11: 유저 이미지 클릭 관리폼 이동 | E11: =세부채점표!E11 -> 0.1
C12: 7 | D12: 검색 빈칸 - 전체 | E12: =세부채점표!E12 -> 0.2
C13: 8 | D13: 검색시 1개 카테고리 트리 제어 | E13: =세부채점표!E13 -> 0.5
C14: 9 | D14: 검색시 2개이상 카테고리시 전체 제어 | E14: =세부채점표!E14 -> 0.5
C15: 10 | D15: 로그인시 처리 | E15: =세부채점표!E15 -> 0.4
C16: 11 | D16: 전체클릭시 전체 제어 | E16: =세부채점표!E16 -> 0.2
C17: 12 | D17: 카테고리 클릭시 검색 | E17: =세부채점표!E17 -> 0.2
A18: 소계 | E18: =SUM(E6:E17) -> 5.5 | F18: =SUM(F6:F17) -> 0 | G18: =SUM(G6:G17) -> 0 | H18: =SUM(H6:H17) -> 0 | I18: =SUM(I6:I17) -> 0 | J18: =SUM(J6:J17) -> 0 | K18: =SUM(K6:K17) -> 0 | L18: =SUM(L6:L17) -> 0 | ... O18: =SUM(O6:O17) -> 0
A19: 문제 1-2 | B19: 로그인 | C19: 1 | D19: 폼 디자인 | E19: =세부채점표!E19 -> 0.2
C20: 2 | D20: 로그인 제어 | E20: =SUM(세부채점표!E20:E23) -> 0.8
A21: 소계 | E21: =SUM(E19:E20) -> 1 | F21: =SUM(F19:F20) -> 0 | G21: =SUM(G19:G20) -> 0 | H21: =SUM(H19:H20) -> 0 | I21: =SUM(I19:I20) -> 0 | J21: =SUM(J19:J20) -> 0 | K21: =SUM(K19:K20) -> 0 | L21: =SUM(L19:L20) -> 0 | ... O21: =SUM(O19:O20) -> 0
A22: 문제 1-3 | B22: 상품 | C22: 1 | D22: 폼디자인 | E22: =세부채점표!E25 -> 1
C23: 2 | D23: 사이즈 제어 | E23: =세부채점표!E26 -> 0.4
C24: 3 | D24: 서브카테고리 클릭 | E24: =세부채점표!E27 -> 0.4
C25: 4 | D25: 서브 클릭시 초기와 | E25: =세부채점표!E28 -> 0.2
C26: 5 | D26: 할은금액 계산 | E26: =세부채점표!E29 -> 0.5
C27: 6 | D27: 구매버튼 제어 | E27: =세부채점표!E30 -> 0.2
C28: 7 | D28: 장바구니 제어 | E28: =세부채점표!E31 -> 0.2
C29: 8 | D29: 20글자 이상... | E29: =세부채점표!E32 -> 0.2
C30: 9 | D30: 별점 | E30: =세부채점표!E33 -> 0.5
A31: 소계 | E31: =SUM(E22:E30) -> 3.6 | F31: =SUM(F22:F30) -> 0 | G31: =SUM(G22:G30) -> 0 | H31: =SUM(H22:H30) -> 0 | I31: =SUM(I22:I30) -> 0 | J31: =SUM(J22:J30) -> 0 | K31: =SUM(K22:K30) -> 0 | L31: =SUM(L22:L30) -> 0 | ... O31: =SUM(O22:O30) -> 0
A32: 문제 1-4 | B32: 마이페이지 | C32: 1 | D32: 정보수정 | E32: =SUM(세부채점표!E35:E41) -> 3
C33: 2 | D33: 구매목록 | E33: =SUM(세부채점표!E42:E45) -> 1.6
C34: 3 | D34: 장바구니 | E34: =SUM(세부채점표!E46:E50) -> 2.3
A35: 소계 | E35: =SUM(E32:E34) -> 6.9 | F35: =SUM(F32:F34) -> 0 | G35: =SUM(G32:G34) -> 0 | H35: =SUM(H32:H34) -> 0 | I35: =SUM(I32:I34) -> 0 | J35: =SUM(J32:J34) -> 0 | K35: =SUM(K32:K34) -> 0 | L35: =SUM(L32:L34) -> 0 | ... O35: =SUM(O32:O34) -> 0
A36: 문제 1-5 | B36: 충전 | C36: 1 | D36: 폼 디자인 | E36: =세부채점표!E52 -> 0.2
C37: 2 | D37: 취소버튼 제어 | E37: =세부채점표!E53 -> 0.1
C38: 3 | D38: - + 버튼 | E38: =세부채점표!E54 -> 0.8
C39: 4 | D39: DB 수정 | E39: =세부채점표!E55 -> 1
A40: 소계 | E40: =SUM(E36:E39) -> 2.1 | F40: =SUM(F36:F39) -> 0 | G40: =SUM(G36:G39) -> 0 | H40: =SUM(H36:H39) -> 0 | I40: =SUM(I36:I39) -> 0 | J40: =SUM(J36:J39) -> 0 | K40: =SUM(K36:K39) -> 0 | L40: =SUM(L36:L39) -> 0 | ... O40: =SUM(O36:O39) -> 0
...

Sheet 게시용
A1: 2025지방 2과제 채점기준
A2: 문제 | B2: 항목 | C2: 세부항목 | E2: 배점 | F2: 배점
B3: 공통사항 | C3: 1 | D3: 로고 메인 이동 (폼 9개) | E3: =전산용!E2 -> 1 | F3: =E6 -> 2.2
C4: 2 | D4: 경고 메시지/정보 메시지 | E4: =전산용!E3 -> 0.2
C5: 3 | D5: 상품, 회원이미지 blob | E5: =전산용!E4 -> 1
A6: 소계 | E6: =전산용!E5 -> 2.2
A7: 문제 1-1 | B7: 메인 폼 | C7: 1 | D7: 디자인 | E7: =전산용!E6 -> 1 | F7: =E19 -> 5.5
C8: 2 | D8: 상품 글자 15자이상 … | E8: =전산용!E7 -> 0.2
C9: 3 | D9: 할인율 계산 | E9: =전산용!E8 -> 0.5
C10: 4 | D10: 상품 클릭 제어 (로그인전 / 로그인후 이동) | E10: =전산용!E9 -> 0.2
C11: 5 | D11: 가격순(↓), 가격순(↑), 별점순(↓) 버튼 제어 | E11: =전산용!E10 -> 1.5
C12: 6 | D12: 유저 이미지 클릭 관리폼 이동 | E12: =전산용!E11 -> 0.1
C13: 7 | D13: 검색 빈칸 - 전체 | E13: =전산용!E12 -> 0.2
C14: 8 | D14: 검색시 1개 카테고리 트리 제어 | E14: =전산용!E13 -> 0.5
C15: 9 | D15: 검색시 2개이상 카테고리시 전체 제어 | E15: =전산용!E14 -> 0.5
C16: 10 | D16: 로그인시 처리 | E16: =전산용!E15 -> 0.4
C17: 11 | D17: 전체클릭시 전체 제어 | E17: =전산용!E16 -> 0.2
C18: 12 | D18: 카테고리 클릭시 검색 | E18: =전산용!E17 -> 0.2
A19: 소계 | E19: =전산용!E18 -> 5.5
A20: 문제 1-2 | B20: 로그인 | C20: 1 | D20: 폼 디자인 | E20: =전산용!E19 -> 0.2 | F20: =E22 -> 1
C21: 2 | D21: 로그인 제어 | E21: =전산용!E20 -> 0.8
A22: 소계 | E22: =전산용!E21 -> 1
A23: 문제 1-3 | B23: 상품 | C23: 1 | D23: 폼디자인 | E23: =전산용!E22 -> 1 | F23: =E32 -> 3.6
C24: 2 | D24: 사이즈 제어 | E24: =전산용!E23 -> 0.4
C25: 3 | D25: 서브카테고리 클릭 | E25: =전산용!E24 -> 0.4
C26: 4 | D26: 서브 클릭시 초기와 | E26: =전산용!E25 -> 0.2
C27: 5 | D27: 할은금액 계산 | E27: =전산용!E26 -> 0.5
C28: 6 | D28: 구매버튼 제어 | E28: =전산용!E27 -> 0.2
C29: 7 | D29: 장바구니 제어 | E29: =전산용!E28 -> 0.2
C30: 8 | D30: 20글자 이상... | E30: =전산용!E29 -> 0.2
C31: 9 | D31: 별점 | E31: =전산용!E30 -> 0.5
A32: 소계 | E32: =전산용!E31 -> 3.6
A33: 문제 1-4 | B33: 마이페이지 | C33: 1 | D33: 정보수정 | E33: =전산용!E32 -> 3 | F33: =E36 -> 6.9
C34: 2 | D34: 구매목록 | E34: =전산용!E33 -> 1.6
C35: 3 | D35: 장바구니 | E35: =전산용!E34 -> 2.3
A36: 소계 | E36: =전산용!E35 -> 6.9
A37: 문제 1-5 | B37: 충전 | C37: 1 | D37: 폼 디자인 | E37: =전산용!E36 -> 0.2 | F37: =E41 -> 2.1
C38: 2 | D38: 취소버튼 제어 | E38: =전산용!E37 -> 0.1
C39: 3 | D39: - + 버튼 | E39: =전산용!E38 -> 0.8
C40: 4 | D40: DB 수정 | E40: =전산용!E39 -> 1
...
